{"uri":"file:///home/tarcisio/dev/phpfin/vendor/symfony/console/Event/ConsoleExceptionEvent.php","root":{"kind":0,"name":"","children":[{"kind":512,"name":"Symfony\\Component\\Console\\Event","location":[11,0,11,42]},{"kind":1,"name":"Command","modifiers":4096,"location":[13,4,13,45],"associated":[{"kind":1,"name":"Symfony\\Component\\Console\\Command\\Command"}]},{"kind":1,"name":"InputInterface","modifiers":4096,"location":[14,4,14,50],"associated":[{"kind":1,"name":"Symfony\\Component\\Console\\Input\\InputInterface"}]},{"kind":1,"name":"OutputInterface","modifiers":4096,"location":[15,4,15,52],"associated":[{"kind":1,"name":"Symfony\\Component\\Console\\Output\\OutputInterface"}]},{"kind":1,"name":"Symfony\\Component\\Console\\Event\\ConsoleExceptionEvent","location":[22,0,66,1],"associated":[{"kind":1,"name":"Symfony\\Component\\Console\\Event\\ConsoleEvent"}],"description":"Allows to handle exception thrown in a command.","children":[{"kind":16,"name":"$exception","modifiers":4,"location":[24,12,24,22],"scope":"Symfony\\Component\\Console\\Event\\ConsoleExceptionEvent"},{"kind":16,"name":"$exitCode","modifiers":4,"location":[25,12,25,21],"scope":"Symfony\\Component\\Console\\Event\\ConsoleExceptionEvent"},{"kind":32,"name":"__construct","modifiers":1,"location":[27,4,33,5],"scope":"Symfony\\Component\\Console\\Event\\ConsoleExceptionEvent","children":[{"kind":128,"name":"$command","location":[27,32,27,48],"scope":"__construct","typeSource":1,"type":"Symfony\\Component\\Console\\Command\\Command"},{"kind":128,"name":"$input","location":[27,50,27,71],"scope":"__construct","typeSource":1,"type":"Symfony\\Component\\Console\\Input\\InputInterface"},{"kind":128,"name":"$output","location":[27,73,27,96],"scope":"__construct","typeSource":1,"type":"Symfony\\Component\\Console\\Output\\OutputInterface"},{"kind":128,"name":"$exception","location":[27,98,27,119],"scope":"__construct","typeSource":1,"type":"Exception"},{"kind":128,"name":"$exitCode","location":[27,121,27,130],"scope":"__construct"}]},{"kind":32,"name":"getException","modifiers":1,"location":[40,4,43,5],"description":"Returns the thrown exception.","scope":"Symfony\\Component\\Console\\Event\\ConsoleExceptionEvent","type":"Exception"},{"kind":32,"name":"setException","modifiers":1,"location":[52,4,55,5],"description":"Replaces the thrown exception.\n\nThis exception will be thrown if no response is set in the event.","scope":"Symfony\\Component\\Console\\Event\\ConsoleExceptionEvent","children":[{"kind":128,"name":"$exception","location":[52,33,52,54],"description":"The thrown exception","scope":"setException","typeSource":1,"type":"Exception"}]},{"kind":32,"name":"getExitCode","modifiers":1,"location":[62,4,65,5],"description":"Gets the exit code.","scope":"Symfony\\Component\\Console\\Event\\ConsoleExceptionEvent","type":"int"}]}]}}